Workbook

Sheet Acess
A1: Empresa: Mozambique Support Services, Lda
A2: Nuit:
A3: Periodo:
A5: Entradas e Saidas bancárias
A7: a) Acess bank
A8: 2025
A10: N/O | B10: Data | C10: Descrição | D10: Entradas | E10: Saidas | F10: Saldo | G10: Observação
A11: 1 | C11: Saldos Anteriores | F11: 457885.89
A12: 2 | B12: 45870 | C12: Transferencia pure diets | D12: 203058.68 | F12: =+F11+D12-E12 -> 660944.57
A13: 3 | B13: 45874 | C13: Pagamento de IVA | E13: 10915 | F13: =+F12+D13-E13 -> 650029.57
A14: 4 | B14: 45880 | C14: Pagamento de INSS | E14: 8637.11 | F14: =+F13+D14-E14 -> 641392.46
A15: 5 | B15: 45880 | C15: Recebimento Pure diets | D15: 1106553 | F15: =+F14+D15-E15 -> 1747945.5
A16: 6 | B16: 45881 | C16: Transferencia C&J | E16: 687341.15 | F16: =+F15+D16-E16 -> 1060604.3
A17: 7 | B17: 45883 | C17: Pagamento INAMAR | E17: 80000 | F17: =+F16+D17-E17 -> 980604.31
A18: 8 | B18: 45883 | C18: Transferencia C&J | E18: 138749.52 | F18: =+F17+D18-E18 -> 841854.79
A19: 9 | B19: 45890 | C19: Transferencia C&J | E19: 193977.86 | F19: =+F18+D19-E19 -> 647876.93
A20: 10 | B20: 45890 | C20: comissao do banco | E20: 99.75 | F20: =+F19+D20-E20 -> 647777.18
A21: 11 | B21: 45890 | C21: Imposto de selo | E21: 2 | F21: =+F20+D21-E21 -> 647775.18
A22: 12 | B22: 45891 | C22: IRPS | E22: 8685.72 | F22: =+F21+D22-E22 -> 639089.46
A23: 13 | B23: 45897 | C23: recebimento C&j | D23: 130000 | F23: =+F22+D23-E23 -> 769089.46
A24: 14 | B24: 45897 | C24: Pagamento Helder contabilidade | E24: 11000 | F24: =+F23+D24-E24 -> 758089.46
A25: 15 | B25: 45897 | C25: Carregamentos salarios | E25: 65000 | F25: =+F24+D25-E25 -> 693089.46
A26: 16 | C26: comissao do banco | E26: 126 | F26: =+F25+D26-E26 -> 692963.46
A27: 17 | E27: 3.2 | F27: =+F26+D27-E27 -> 692960.26
A28: 18 | E28: 51000 | F28: =+F27+D28-E28 -> 641960.26
A29: 19 | E29: 31500 | F29: =+F28+D29-E29 -> 610460.26
A30: 20 | E30: 630 | F30: =+F29+D30-E30 -> 609830.26
A31: 21 | D31: 384097.9 | F31: =+F30+D31-E31 -> 993928.16
A32: 22 | E32: 15500 | F32: =+F31+D32-E32 -> 978428.16
A33: 23 | E33: 291384.82 | F33: =+F32+D33-E33 -> 687043.34
D34: 31500 | F34: =+F33+D34-E34 -> 718543.34
D35: 630 | F35: =+F34+D35-E35 -> 719173.34
E36: 954 | F36: =+F35+D36-E36 -> 718219.34
E37: 18.9 | F37: =+F36+D37-E37 -> 718200.44
E38: 45000 | F38: =+F37+D38-E38 -> 673200.44
D39: 40209.11 | F39: =+F38+D39-E39 -> 713409.55
E40: 30000 | F40: =+F39+D40-E40 -> 683409.55
E41: 315 | F41: =+F40+D41-E41 -> 683094.55
E42: 6.3 | F42: =+F41+D42-E42 -> 683088.25
E43: 265000 | F43: =+F42+D43-E43 -> 418088.25
...

Sheet EXTRATO PURE DIETS
A1: MOZAMBIQUE SUPPORT SERVICES, Lda
A2: =+Acess!A2 -> Nuit: | B2: 401761349
A3: =+Acess!A3 -> Periodo: | B3: 2025
A7: a) PURE DIETS
A8: EXTRATO DO CLIENTE
A10: N/O | B10: Data | C10: Descrição | D10: Dif. Arred. | E10: Dif. Cambio | F10: Debito | G10: Credito | H10: Saldo
H12: =SUM(F11-G12) -> 0
A13: 1 | C13: Brd 20-05 | D13: 0,0O | E13: 0,0O | F13: 819023.99 | H13: =+H12+F13-G13 -> 819023.99
A14: 2 | C14: RE Nº 2/2025 | D14: 0,0O | E14: 0,0O | F14: 41617.23 | H14: =+H13+F14-G14 -> 860641.22
A15: 5 | C15: RE Nº 3/2025 | D15: 0,0O | E15: 0,0O | G15: 709363 | H15: =+H14+F15-G15 -> 151278.22
A16: 6 | C16: FA Nº 3/2025 | D16: 0,0O | E16: 0,0O | F16: 957568.63 | H16: =+H15+F16-G16 -> 1108846.9
A17: 7 | C17: FA Nº 4/2025 | D17: 0,0O | E17: 0,0O | F17: 243595.63 | H17: =+H16+F17-G17 -> 1352442.5
D18: 0,0O | E18: 0,0O | G18: 2299407.4 | H18: =+H17+F18-G18 -> -946964.96
A19: 8 | C19: RE Nº 4/2025 | D19: 0,0O | E19: 0,0O | G19: 1088875.3 | H19: =+H18+F19-G19 -> -2035840.2
A20: 9 | C20: FA Nº 7/2025 | D20: 0,0O | E20: 0,0O | F20: 343193.13 | H20: =+H19+F20-G20 -> -1692647.1
A21: 10 | C21: FA Nº 5/2025 | D21: 0,0O | E21: 0,0O | F21: 111408.39 | H21: =+H20+F21-G21 -> -1581238.7
A22: 11 | C22: FA Nº 6/2025 | D22: 0,0O | E22: 0,0O | F22: 271435.76 | H22: =+H21+F22-G22 -> -1309803
A23: 12 | C23: FA Nº 8/2025 | D23: 0,0O | E23: 0,0O | F23: 105343.93 | H23: =+H22+F23-G23 -> -1204459
A24: 13 | C24: FA Nº 11/2025 | D24: 0,0O | E24: 0,0O | F24: 85723.59 | H24: =+H23+F24-G24 -> -1118735.4
A25: 14 | C25: FA Nº 14/2025 | D25: 0,0O | E25: 0,0O | F25: 95751.82 | H25: =+H24+F25-G25 -> -1022983.6
A26: 15 | C26: FA Nº 9/2025 | D26: 0,0O | E26: 0,0O | F26: 119203.64 | H26: =+H25+F26-G26 -> -903779.98
A27: 16 | C27: FA Nº 10/2025 | D27: 0,0O | E27: 0,0O | F27: 237349.29 | H27: =+H26+F27-G27 -> -666430.69
A28: 17 | C28: FA Nº 12/2025 | D28: 0,0O | E28: 0,0O | F28: 16173.1 | H28: =+H27+F28-G28 -> -650257.59
A29: 18 | C29: FA Nº 13/2025 | D29: 0,0O | E29: 0,0O | F29: 13852.31 | H29: =+H28+F29-G29 -> -636405.28
A30: 19 | C30: FA Nº 16/2025 | D30: 0,0O | E30: 0,0O | F30: 37180.77 | H30: =+H29+F30-G30 -> -599224.51
A31: 20 | C31: FA Nº 15/2025 | D31: 0,0O | E31: 0,0O | F31: 46480.02 | H31: =+H30+F31-G31 -> -552744.49
A32: 21 | C32: RE Nº 5/2025 | D32: 0,0O | E32: 0,0O | G32: 1088807.3 | H32: =+H31+F32-G32 -> -1641551.8
A33: 22 | C33: RE Nº 6/2025 | D33: 0,0O | E33: 0,0O | H33: =+H32+F33-G33 -> -1641551.8
A34: 23 | C34: FA Nº 18/2025 | D34: 0,0O | E34: 0,0O | F34: 786208.37 | H34: =+H33+F34-G34 -> -855343.43
A35: 24 | C35: FA Nº 17/2025 | D35: 0,0O | E35: 0,0O | F35: 113658.39 | H35: =+H34+F35-G35 -> -741685.04
A36: 25 | C36: FA Nº 37/2025 | D36: 0,0O | E36: 0,0O | F36: 34378.56 | H36: =+H35+F36-G36 -> -707306.48
A37: 26 | C37: FA Nº 38/2025 | D37: 0,0O | E37: 0,0O | F37: 160365.85 | H37: =+H36+F37-G37 -> -546940.63
A38: 27 | C38: RE Nº 7/2025 | D38: 0,0O | E38: 0,0O | G38: 1479316.3 | H38: =+H37+F38-G38 -> -2026256.9
A39: 28 | C39: FA Nº 39/2025 | D39: 0,0O | E39: 0,0O | F39: 15446.04 | H39: =+H38+F39-G39 -> -2010810.8
A40: 29 | C40: FA Nº 42/2025 | D40: 0,0O | E40: 0,0O | F40: 52997.04 | H40: =+H39+F40-G40 -> -1957813.8
A41: 30 | C41: FA Nº 43/2025 | D41: 0,0O | E41: 0,0O | F41: 26002.03 | H41: =+H40+F41-G41 -> -1931811.8
A42: 31 | C42: FA Nº 44/2025 | D42: 0,0O | E42: 0,0O | F42: 24186.42 | H42: =+H41+F42-G42 -> -1907625.4
A43: 32 | C43: FA Nº 45/2025 | D43: 0,0O | E43: 0,0O | F43: 116624.49 | H43: =+H42+F43-G43 -> -1791000.9
A44: 33 | C44: FA Nº 46/2025 | D44: 0,0O | E44: 0,0O | F44: 27119.53 | H44: =+H43+F44-G44 -> -1763881.3
A45: 34 | C45: FA Nº 48/2025 | D45: 0,0O | E45: 0,0O | F45: 238719.87 | H45: =+H44+F45-G45 -> -1525161.5
...

Sheet Uba
A1: =+Acess!A1 -> Empresa: Mozambique Support Services, Lda
A2: =+Acess!A2 -> Nuit:
A3: =+Acess!A3 -> Periodo:
A4: =+Acess!A4 -> 0
A5: Entradas e Saidas bancárias
A7: a)UBA BANK
A8: Novembro
A10: N/O | B10: Data | C10: Descrição | D10: Entradas | E10: Saidas | F10: Saldo | G10: Observação
F12: =+F11+D12-E12 -> 0
F13: =+F12+D13-E13 -> 0
F14: =+F13+D14-E14 -> 0
F15: =+F14+D15-E15 -> 0
F16: =+F15+D16-E16 -> 0
F17: =+F16+D17-E17 -> 0
F18: =+F17+D18-E18 -> 0
F19: =+F18+D19-E19 -> 0
F20: =+F19+D20-E20 -> 0
F21: =+F20+D21-E21 -> 0
F22: =+F21+D22-E22 -> 0
F23: =+F22+D23-E23 -> 0
... F194: =+F193+D194-E194 -> 0
F195: =+F194+D195-E195 -> 0 | G195: Sem comprovativo
F196: =+F195+D196-E196 -> 0 | G196: Sem comprovativo
F197: =+F196+D197-E197 -> 0
F198: =+F197+D198-E198 -> 0
F199: =+F198+D199-E199 -> 0
F200: =+F199+D200-E200 -> 0
F201: =+F200+D201-E201 -> 0
F202: =+F201+D202-E202 -> 0
F203: =+F202+D203-E203 -> 0
F204: =+F203+D204-E204 -> 0
F205: =+F204+D205-E205 -> 0
F206: =+F205+D206-E206 -> 0
F207: =+F206+D207-E207 -> 0
F208: =+F207+D208-E208 -> 0
... F286: =+F285+D286-E286 -> 0
F287: =+F286+D287-E287 -> 0 | G287: Falta Recibo e Borderou
F288: =+F287+D288-E288 -> 0
F289: =+F288+D289-E289 -> 0
F290: =+F289+D290-E290 -> 0
...

Sheet Caixa Outubro
A1: =+Acess!A1 -> Empresa: Mozambique Support Services, Lda
A2: =+Acess!A2 -> Nuit: | B2: 401761349
A3: =+Acess!A3 -> Periodo: | B3: 2025
A5: Entradas e Saidas Caixa
A7: a) Caixa
A8: Outubro
A10: N/O | B10: Data | C10: Descrição | D10: N° Documento | E10: Nome da Entidade | F10: Entradas | G10: Saidas | H10: Saldo | I10: Observação
A11: 1 | C11: Reforco de caixa | F11: 50000
A12: 2 | C12: Autenticacaoo de documentos | E12: Notario | G12: 2000 | H12: =SUM(F11-G12) -> 48000
A13: 3 | C13: INSS | E13: INSS | G13: 8998 | H13: =+H12+F13-G13 -> 39002
A14: 4 | C14: Aviso | E14: Autoridade tributaria | G14: 6152.46 | H14: =+H13+F14-G14 -> 32849.54
A16: 5 | C16: Irps | E16: Autoridade tributaria | G16: 6685.72 | H16: =+H14+F16-G16 -> 26163.82
A17: 6 | C17: Aeroporto e Mhs | E17: Taxas Aeroportuarias | G17: 4155 | H17: =+H16+F17-G17 -> 22008.82
A18: 7 | C18: Vicente Yango | E18: Inscricao do yango | G18: 300 | H18: =+H17+F18-G18 -> 21708.82
A19: 8 | C19: TV cabo | E19: TV CABO | G19: 5750 | H19: =+H18+F19-G19 -> 15958.82
A20: 9 | C20: Agua de Maputo | E20: AdRM | G20: 1470 | H20: =+H19+F20-G20 -> 14488.82
A21: 10 | C21: Aviso | E21: Autoridade tributaria | G21: 3957.33 | H21: =+H20+F21-G21 -> 10531.49
A22: 11 | C22: pilhas | E22: para ambientadores | G22: 260 | H22: =+H21+F22-G22 -> 10271.49
A23: 12 | C23: Aviso | E23: Alfandegas | G23: 8375.08 | H23: =+H22+F23-G23 -> 1896.41
A24: 13 | C24: MAHS | E24: Taxas Aeroportuarias | G24: 1226 | H24: =+H23+F24-G24 -> 670.41
A25: 14 | C25: Yango MBT | E25: Entrega de documentos | G25: 150 | H25: =+H24+F25-G25 -> 520.41
A26: 15 | C26: Reforco de caixa | F26: 15000 | H26: =+H25+F26-G26 -> 15520.41
A27: 16 | C27: Pagamento de Aviso | E27: Deposito Banco | G27: 5924.64 | H27: =+H26+F27-G27 -> 9595.77
A28: 17 | C28: Credelec | E28: Emola | G28: 2000 | H28: =+H27+F28-G28 -> 7595.77
A29: 18 | C29: Pasta de Arquivos | E29: Academy | G29: 435 | H29: =+H28+F29-G29 -> 7160.77
A30: 19 | C30: Reforco de caixa | F30: 45000 | H30: =+H29+F30-G30 -> 52160.77
A31: 20 | C31: Pagamento de Aviso | G31: 30101.68 | H31: =+H30+F31-G31 -> 22059.09
A32: 21 | C32: mahs e Aeroportos | E32: Taxas Aeroportuarias | G32: 5950 | H32: =+H31+F32-G32 -> 16109.09
A33: 22 | C33: Afonso Domingos | E33: MSS | G33: 10000 | H33: =+H32+F33-G33 -> 6109.09 | I33: Salario referente ao mes de Outubro
A34: 23 | C34: Almoco colega Valda | G34: 300 | H34: =+H33+F34-G34 -> 5809.09
A35: 24 | C35: Moldura Alvara | E35: MSS | G35: 4005 | H35: =+H34+F35-G35 -> 1804.09
A36: 25 | C36: Papel higienico | E36: MSS | G36: 390 | H36: =+H35+F36-G36 -> 1414.09
A37: 26 | C37: Recarga credito | E37: MSS | G37: 500 | H37: =+H36+F37-G37 -> 914.09
A38: 27 | C38: PREGOS | G38: 30.09 | H38: =+H37+F38-G38 -> 884
A39: 28 | C39: yango acess | G39: 384 | H39: =+H38+F39-G39 -> 500
A40: 29 | C40: SALDO FINAL | H40: =+H39+F40-G40 -> 500

Sheet Saidas nao ducumentadas
A1: =+Acess!A1 -> Empresa: Mozambique Support Services, Lda
A2: =+Acess!A2 -> Nuit:
A3: =+Acess!A3 -> Periodo:
A5: Entradas e Saidas Bancarias Nao Documentadas
A7: a)
A8: Novembro (Bim)
A10: N/O | B10: Data | C10: Descrição | D10: Entradas | E10: Saidas | F10: Saldo | G10: Observação
A13: 1 | F13: =F12+D13-E13 -> 0
F14: =F13+D14-E14 -> 0
F15: =F14+D15-E15 -> 0
F16: =F15+D16-E16 -> 0
F17: =F16+D17-E17 -> 0
F18: =F17+D18-E18 -> 0
F19: =F18+D19-E19 -> 0
F20: =F19+D20-E20 -> 0
F21: =F20+D21-E21 -> 0
F22: =F21+D22-E22 -> 0
F23: =F22+D23-E23 -> 0
F24: =F23+D24-E24 -> 0
F25: =F24+D25-E25 -> 0
... F83: =F82+D83-E83 -> 0
A84: 2 | F84: =F83+D84-E84 -> 0
A85: =A84+1 -> 3 | F85: =F84+D85-E85 -> 0
A86: =A85+1 -> 4 | F86: =F85+D86-E86 -> 0
A87: =A86+1 -> 5 | F87: =F86+D87-E87 -> 0
A88: =A87+1 -> 6 | F88: =F87+D88-E88 -> 0
C90: Total | D90: =SUM(D13:D89) -> 0 | E90: =SUM(E84:E89) -> 0 | F90: =D90-E90 -> 0
A93: Mapa preparado aos…………../……………./…………………
A94: Por…………………………………………………………………………………………………..

Sheet C&J logistica
A1: =+Acess!A1 -> Empresa: Mozambique Support Services, Lda
A2: =+Acess!A2 -> Nuit: | B2: 401761349
A3: =+Acess!A3 -> Periodo:
A6: Extracto de Clientes : C&J LOGISTICA
A9: 1)
A10: N/O | B10: Data | C10: Descrição | D10: Movimentos | F10: Saldo | G10: Observação
D11: Débito | E11: Crédito
F13: =+F12+D13-E13 -> 0
F14: =+F13+D14-E14 -> 0
F15: =+F14+D15-E15 -> 0
F16: =+F15+D16-E16 -> 0
F17: =+F16+D17-E17 -> 0
F18: =+F17+D18-E18 -> 0
F19: =+F18+D19-E19 -> 0
B21: Total | D21: =SUM(D12:D19) -> 0 | E21: =SUM(E12:E19) -> 0 | F21: =D21-E21 -> 0
A24: 2)
A25: N/O | B25: Data | C25: Descrição | D25: Movimentos | F25: Saldo | G25: Observação
D26: Débito | E26: Crédito
F28: =+F27+D28-E28 -> 0
F29: =+F28+D29-E29 -> 0
F30: =+F29+D30-E30 -> 0
F31: =+F30+D31-E31 -> 0
F32: =+F31+D32-E32 -> 0
F33: =+F32+D33-E33 -> 0
F34: =+F33+D34-E34 -> 0
B36: Total | D36: =SUM(D27:D29) -> 0 | E36: =SUM(E27:E29) -> 0 | F36: =D36-E36 -> 0
A39: 3)
A40: N/O | B40: Data | C40: Descrição | D40: Movimentos | F40: Saldo | G40: Observação
D41: Débito | E41: Crédito
F43: =+F42+D43-E43 -> 0
F44: =+F43+D44-E44 -> 0
F45: =+F44+D45-E45 -> 0
F46: =+F45+D46-E46 -> 0
F47: =+F46+D47-E47 -> 0
F48: =+F47+D48-E48 -> 0
F49: =+F48+D49-E49 -> 0
B51: Total | D51: =SUM(D42:D44) -> 0 | E51: =SUM(E42:E46) -> 0 | F51: =D51-E51 -> 0
A54: Adiantamentos
A56: 1)
A57: N/O | B57: Data | C57: Descrição | D57: Movimentos | F57: Saldo | G57: Observação
...

Sheet 25% De Agenciamento
C2: Setembro | J2: Outubro
A15: Ordem | B15: Agenciamento | C15: Agenciamento total | D15: FACTURA C&J Logistica | E15: 0.75 | F15: 0.25 | H15: Ordem | I15: Agenciamento | J15: Agenciamento total | K15: FACTURA C&J Logistica | L15: 0.75 | M15: 0.25
B16: sem IVA | C16: (IVA INCLUIDO) | E16: CJ Logistica | F16: MSS | I16: sem IVA | J16: (IVA INCLUIDO) | L16: CJ Logistica | M16: MSS
A17: 1 | B17: 5330.23 | C17: 6183.06 | D17: 2025/286 | E17: 4637.3 | F17: 1545.77 | H17: 1 | I17: 29485.45 | J17: 34203.12 | K17: 2025-429 | L17: 25652.34 | M17: 8550.78
A18: 2 | B18: 2000 | C18: 2320 | D18: 2025/287 | E18: 1740 | F18: 580 | H18: 2 | I18: 13629.01 | J18: 15809.65 | K18: 2025-0430 | L18: 13280.11 | M18: 3952.4
A19: 3 | B19: 2000 | C19: 2320 | D19: 2025/288 | E19: 1740 | F19: 580 | H19: 3 | I19: 3922.61 | J19: 4550.23 | K19: 2025-0431 | L19: 3822.2 | M19: 1137.6
A20: 4 | B20: 5000 | C20: 5800 | D20: 2025/305 | E20: 4350 | F20: 1450 | H20: 4 | I20: 3500 | J20: 4060 | K20: 2025-0333 | L20: 3410.4 | M20: 1015
A21: 5 | B21: 5000 | C21: 5800 | D21: 2025/306 | E21: 4350 | F21: 1450 | H21: 5 | I21: 3500 | J21: 4060 | K21: 2025-0334 | L21: 3410.4 | M21: 1015
A22: 6 | B22: 10915.76 | C22: 12662.3 | D22: 2025/307 | E22: 9496.72 | F22: 3165.575 | H22: 6 | I22: 5000 | J22: 5800 | K22: 2025-0433 | L22: 4350 | M22: 1450
A23: 7 | B23: 5000 | C23: 5800 | D23: 2025/308 | E23: 4350 | F23: 1450 | H23: 7 | I23: 5000 | J23: 5800 | K23: 2025-0434 | L23: 4350 | M23: 1450
A24: 8 | B24: 2000 | C24: 2320 | D24: 2025/332 | E24: 1740 | F24: 580 | H24: 8 | I24: 11377.69 | J24: 13198.12 | K24: 2025-0414 | L24: 9898.59 | M24: 3299.53
A25: 9 | B25: 5302.45 | C25: 6150.84 | D25: 2025/335 | E25: 4613.13 | F25: 1537.71 | H25: 9 | I25: 24863.13 | J25: 28841.23 | K25: 2025-0439 | L25: 21630.93 | M25: 7210.3
A26: 10 | B26: 2000 | C26: 2320 | D26: 2025/352 | E26: 1740 | F26: 580 | H26: 10 | I26: 5000 | J26: 5800 | K26: 2025-0395 | L26: 4350 | M26: 1450
A27: 11 | B27: 5000 | C27: 5800 | D27: 2025/353 | E27: 4350 | F27: 1450 | H27: 11
A28: 12 | B28: 5000 | C28: 5800 | D28: 2025/354 | E28: 4350 | F28: 1450 | H28: 12
A29: 13 | B29: 5000 | C29: 5800 | D29: 2025/355 | E29: 4350 | F29: 1450 | H29: 13
A30: 14 | H30: 14
A31: 15 | H31: 15
A32: 16 | H32: 16
A34: TOTAL | B34: =SUM(B17+B18+B19+B20+B21+B22+B23+B24+B25+B26+B27+B28+B29+B30+B31+B32) -> 59548.44 | C34: =SUM(C32+C31+C30+C29+C28+C27+C26+C25+C24+C23+C22+C21+C20+C19+C18+C17) -> 69076.2 | E34: =SUM(E17+E18+E19+E20+E21+E22+E23+E24+E25+E26+E27+E28+E29+E30+E31+E32) -> 51807.15 | F34: =SUM(F17+F18+F19+F20+F21+F22+F23+F24+F25+F26+F27+F28+F29+F30+F31+F32) -> 17269.055 | H34: TOTAL | I34: =SUM(I17+I18+I19+I20+I21+I22+I23+I24+I25+I26+I27+I28+I29+I30+I31+I32) -> 105277.89 | J34: =SUM(J32+J31+J30+J29+J28+J27+J26+J25+J24+J23+J22+J21+J20+J19+J18+J17) -> 122122.35 | L34: =SUM(L17+L18+L19+L20+L21+L22+L23+L24+L25+L26+L27+L28+L29+L30+L31+L32) -> 94154.97 | M34: =SUM(M17+M18+M19+M20+M21+M22+M23+M24+M25+M26+M27+M28+M29+M30+M31+M32) -> 30530.61
C39: NOVEMBRO | K39: DEZEMBRO
A53: Ordem | B53: Agenciamento | C53: Agenciamento total | D53: FACTURA C&J Logistica | E53: 0.75 | F53: 0.25 | H53: Ordem | I53: Agenciamento | J53: Agenciamento total | K53: FACTURA C&J Logistica | L53: 0.75 | M53: 0.25
B54: sem IVA | C54: (IVA INCLUIDO) | E54: CJ Logistica | F54: MSS | I54: sem IVA | J54: (IVA INCLUIDO) | L54: CJ Logistica | M54: MSS
A55: 1 | B55: 5131.67 | C55: 5952.74 | D55: FACT 2025/0463 | E55: =C55*0.75 -> 4464.555 | F55: =C55*0.25 -> 1488.185 | H55: 1
A56: 2 | B56: 5000 | C56: =B56*0.16+B56 -> 5800 | D56: FACT 2025/0506 | E56: =C56*0.75 -> 4350 | F56: =C56*0.25 -> 1450 | H56: 2
A57: 3 | B57: 9087 | C57: =B57*0.16+B57 -> 10540.92 | D57: FACT 2025/0505 | E57: =C57*0.75 -> 7905.69 | F57: =C57*0.25 -> 2635.23 | H57: 3
A58: 4 | B58: . | C58: =B58*0.16+B58 -> #VALUE! | D58: FACT 2025/0549 | E58: =C58*0.75 -> #VALUE! | F58: =C58*0.25 -> #VALUE! | H58: 4
A59: 5 | B59: 5000 | C59: =B59*0.16+B59 -> 5800 | D59: FACT 2025/0545 | E59: =C59*0.75 -> 4350 | F59: =C59*0.25 -> 1450 | H59: 5
A60: 6 | B60: 5330.76 | C60: =B60*0.16+B60 -> 6183.6816 | D60: FACT 2025/0548 | E60: =C60*0.75 -> 4637.7612 | F60: =C60*0.25 -> 1545.9204 | H60: 6
A61: 7 | B61: 5000 | C61: =B61*0.16+B61 -> 5800 | D61: FACT 2025/0547 | E61: =C61*0.75 -> 4350 | F61: =C61*0.25 -> 1450 | H61: 7
A62: 8 | B62: 16464 | C62: =B62*0.16+B62 -> 19098.24 | D62: FACT 2025/0544 | E62: =C62*0.75 -> 14323.68 | F62: =C62*0.25 -> 4774.56 | H62: 8
A63: 9 | B63: 50914.95 | C63: =B63*0.16+B63 -> 59061.342 | D63: FACT 2025/0552 | E63: =C63*0.75 -> 44296.006 | F63: =C63*0.25 -> 14765.335 | H63: 9
A64: 10 | B64: 9087 | C64: =B64*0.16+B64 -> 10540.92 | D64: FACT 2025/0553 | E64: =C64*0.75 -> 7905.69 | F64: =C64*0.25 -> 2635.23 | H64: 10
A65: 11 | B65: 7224.47 | C65: =B65*0.16+B65 -> 8380.3852 | D65: FACT 2025/554 | E65: =C65*0.75 -> 6285.2889 | F65: =C65*0.25 -> 2095.0963 | H65: 11
A66: 12 | B66: 5000 | C66: =B66*0.16+B66 -> 5800 | D66: FACT 2025/555 | E66: =C66*0.75 -> 4350 | F66: =C66*0.25 -> 1450 | H66: 12
A67: 13 | B67: 15000 | C67: =B67*0.16+B67 -> 17400 | D67: FACT 2025/556 | E67: =C67*0.75 -> 13050 | F67: =C67*0.25 -> 4350 | H67: 13
A68: 14 | B68: 7908.78 | C68: =B68*0.16+B68 -> 9174.1848 | D68: FACT 2025/558 | E68: =C68*0.75 -> 6880.6386 | F68: =C68*0.25 -> 2293.5462 | H68: 14
A69: 15 | B69: 24863.13 | C69: =B69*0.16+B69 -> 28841.231 | D69: FACT 2025/509 | E69: =C69*0.75 -> 21630.923 | F69: =C69*0.25 -> 7210.3077 | H69: 15
A70: 16 | B70: 5000 | C70: =B70*0.16+B70 -> 5800 | D70: FACT 2025/560 | E70: =C70*0.75 -> 4350 | F70: =C70*0.25 -> 1450 | H70: 16
A72: TOTAL | B72: =SUM(B55+B56+B57+B58+B59+B60+B61+B62+B63+B64+B65+B66+B67+B68+B69+B70) -> #VALUE! | C72: =SUM(C70+C69+C68+C67+C66+C65+C64+C63+C62+C61+C60+C59+C58+C57+C56+C55) -> #VALUE! | E72: =SUM(E55+E56+E57+E58+E59+E60+E61+E62+E63+E64+E65+E66+E67+E68+E69+E70) -> #VALUE! | F72: =SUM(F55+F56+F57+F58+F59+F60+F61+F62+F63+F64+F65+F66+F67+F68+F69+F70) -> #VALUE! | H72: TOTAL | I72: =SUM(I55+I56+I57+I58+I59+I60+I61+I62+I63+I64+I65+I66+I67+I68+I69+I70) -> 0 | J72: =SUM(J70+J69+J68+J67+J66+J65+J64+J63+J62+J61+J60+J59+J58+J57+J56+J55) -> 0 | L72: =SUM(L55+L56+L57+L58+L59+L60+L61+L62+L63+L64+L65+L66+L67+L68+L69+L70) -> 0 | M72: =SUM(M55+M56+M57+M58+M59+M60+M61+M62+M63+M64+M65+M66+M67+M68+M69+M70) -> 0
...

Sheet Acacio despachante
A12: Ordem | B12: Agenciamento | C12: Agenciamento total | D12: Facturas | E12: 0.5 | F12: 0.5
B13: sem IVA | C13: (IVA INCLUIDO) | E13: Acacio Despachante | F13: MSS
A14: 1 | B14: 5000 | C14: 5800 | D14: FeDeX | E14: 2900 | F14: 2900
A15: 2 | B15: 5000 | C15: 5800 | D15: ETIOPHIA AIR | E15: 2900 | F15: 2900
A16: 3 | B16: 5000 | C16: 5800 | D16: FeDeX | E16: 2900 | F16: 2900
A17: 4 | B17: 5000 | C17: 5800 | D17: FeDeX | E17: 2900 | F17: 2900
A18: 5 | B18: 5000 | C18: 5800 | D18: ETIOPHIA | E18: 2900 | F18: 2900
A19: 6 | B19: 5000 | C19: 5800 | D19: FeDeX | E19: 2900 | F19: 2900
A20: 7 | B20: 5000 | C20: 5800 | D20: FeDeX | E20: 2900 | F20: 2900
A21: 8 | B21: 5000 | C21: 5800 | D21: FeDeX | E21: 2900 | F21: 2900
A22: total | B22: =SUM(B18+B17+B16+B15+B14+B19+B20+B21) -> 40000 | C22: =SUM(C18+C17+C16+C15+C14+C20+C19+C21) -> 46400 | D22: …....................... | E22: =SUM(E14+E15+E16+E17+E18+E19+E20+E21) -> 23200 | F22: =SUM(F18+F17+F16+F15+F14+F19+F20+F21) -> 23200
B27: Despesas Assumidas pela AD | C27: VALOR
B28: Taxa de documentação | C28: 1600
B29: Taxa de documentação | C29: 1600
B30: Taxa de documentação | C30: 1600
B31: Taxa de documentação | C31: 1600
B32: Taxa de documentação | C32: 1600
B33: Taxa de documentação | C33: 1600
B34: Taxa de documentação | C34: 1600
B35: TOTAL: | C35: =SUM(C34+C30+C29+C28+C31+C32+C33) -> 11200
A40: Ordem | B40: Agenciamento | C40: Agenciamento total | D40: Facturas | E40: 0.5 | F40: 0.5
B41: sem IVA | C41: (IVA INCLUIDO) | E41: Acacio Despachante | F41: MSS | J41: Despesas Assumidas pela AD | K41: VALOR
A42: 1 | B42: 5000 | C42: 5800 | D42: FeDeX | E42: 2900 | F42: 2900 | J42: Taxa de documentação | K42: 1600
A43: 2 | B43: 5000 | C43: 5800 | D43: ETIOPHIA AIR | E43: 2900 | F43: 2900 | J43: Taxa de documentação | K43: 1600
A44: 3 | B44: 5000 | C44: 5800 | D44: FeDeX | E44: 2900 | F44: 2900 | J44: Taxa de documentação | K44: 1600
A45: 4 | B45: 7500 | C45: =B45*0.16+B45 -> 8700 | D45: FeDeX | E45: 4350 | F45: 4350 | J45: Taxa de documentação | K45: 1600
A46: 5 | B46: 7500 | C46: =B46*0.16+B46 -> 8700 | D46: FeDeX | E46: =C46*0.5 -> 4350 | F46: 4350 | J46: Taxa de documentação | K46: 1600
A47: 6 | B47: 5000 | C47: 5800 | D47: ETIOPHIA | E47: 2900 | F47: 2900 | J47: Taxa de documentação | K47: 1600
A48: 7 | B48: 5000 | C48: 5800 | D48: FEDeX | E48: 2900 | F48: 2900 | J48: Taxa de documentação | K48: 1600
A49: 8 | B49: 5000 | C49: 5800 | D49: FeDeX | E49: 2900 | F49: 2900 | J49: Taxa de documentação | K49: 1600
A50: total | B50: =SUM(B47+B46+B44+B43+B42+B49+B45+B48) -> 45000 | C50: =SUM(C47+C46+C44+C43+C42+C49+C45+C48) -> 52200 | D50: …....................... | E50: =SUM(E42+E43+E44+E46+E47+E49+E45+E48) -> 26100 | F50: =SUM(F47+F46+F44+F43+F42+F49+F45+F48) -> 26100 | J50: Total | K50: =K42+K43+K44+K45+K46+K47+K48+K49 -> 12800
F52: =F50+K50+29878.73 -> 68778.73

Sheet Sheet2
C10: DESPESAS DO ESCRITORIO
B12: DATAS DE PAGAMENTO | C12: DESCRICAO | D12: VALOR | G12: DESCRICAO | H12: VALOR
B13: ATE 10 DE CADA MES | C13: INSS | D13: 4097.36
B14: 46000 | C14: AGUA | D14: 1469.95
B15: ate 20 de cada mes | C15: IRPS | D15: 8685.72
B16: ate 10 de cada mes reporte | C16: IVA
B17: 46003 | C17: TV CABO | D17: 5750
B18: Total : | D18: =D13+D14+D15+D16+D17 -> 20003.03
B24: Cargas | C24: Descricao | D24: Valor
B25: Aereas | C25: Acacio | D25: 36310.94
B26: INV-088018 | C26: C&J Logistica | D26: 107120.54
B27: INV-088019 | C27: C&J Logistica | D27: 33688.23
B28: INV-088020 | C28: C&J Logistica | D28: 76808.95
B29: Total

Sheet Pure diets
A1: =+Acess!A1 -> Empresa: Mozambique Support Services, Lda
A2: =+Acess!A2 -> Nuit:
A3: =+Acess!A3 -> Periodo: | B3: OUTUBRO
A6: Extracto de Clientes à
A9: 1)
A10: N/O | B10: Data | C10: Descrição | D10: Movimentos | F10: Saldo | G10: Observação
D11: Débito | E11: Crédito
A12: 1 | B12: 45932 | C12: POFDMCC/MOZ/2025/015 | D12: 947209.53 | E12: 0 | F12: =SUM(E12-D12) -> -947209.53
A13: 2 | B13: 45932 | C13: POFDMCC-MOZ-25-016 | D13: 60129 | F13: =+F12+E13-D13 -> -1007338.5
A14: 3 | B14: 45932 | C14: POFDMCC-MOZ-25-017 | D14: 42684 | F14: =+F13+E14-D14 -> -1050022.5
A15: 4 | F15: =+F14+E15-D15 -> -1050022.5
A16: 5 | F16: =+F15+E16-D16 -> -1050022.5
A17: 6 | F17: =+F16+E17-D17 -> -1050022.5
A18: 7 | F18: =+F17+E18-D18 -> -1050022.5
A19: 9 | F19: =+F18+D19-E19 -> -1050022.5
A20: 10 | F20: =SUM(+F19+D20-E20) -> -1050022.5
A21: 11 | F21: =+F19+D21-E21 -> -1050022.5
A22: 12 | F22: =SUM(+F21+E22-D22) -> -1050022.5
A23: 13 | F23: =SUM(+F22+E22-D22) -> -1050022.5
B38: Total | D38: =SUM(D12:D23) -> 1050022.5 | E38: =SUM(E12:E23) -> 0 | F38: =D38-E38 -> 1050022.5

Sheet Caixa novembro
A1: =+Acess!A1 -> Empresa: Mozambique Support Services, Lda
A2: =+Acess!A2 -> Nuit: | B2: 401761349
A3: =+Acess!A3 -> Periodo: | B3: 2025
A5: Entradas e Saidas Caixa
A7: a) Caixa
A8: Novembro
A10: N/O | B10: Data | C10: Descrição | D10: N° Documento | E10: Nome da Entidade | F10: Entradas | G10: Saidas | H10: Saldo | I10: Observação
A11: 1 | B11: 45968 | C11: Reforco de caixa | F11: 100000 | I11: Lev. Cheque
A12: 2 | B12: 45968 | C12: Factura da MSC | E12: MSC | G12: 32118.95 | H12: =SUM(F11-G12) -> 67881.05
A13: 3 | B13: 45968 | C13: Nota de DEBITO | E13: MSC | G13: 26450.9 | H13: =+H12+F13-G13 -> 41430.15
A14: 4 | B14: 45968 | C14: INSS | G14: 8204.7 | H14: =+H13+F14-G14 -> 33225.45
A15: 5 | B15: 45968 | C15: Agente MSC | E15: MSC | G15: 29849.82 | H15: =+H14+F15-G15 -> 3375.63
A16: 6 | B16: 45968 | C16: Agua | E16: ADRM | G16: 1470 | H16: =+H15+F16-G16 -> 1905.63
A17: 7 | C17: Reforco de caixa | F17: 16520 | H17: =+H16+F17-G17 -> 18425.63
A18: 8 | C18: Limpeza | G18: 4000 | H18: =+H17+F18-G18 -> 14425.63
A19: 9 | C19: Iirps | G19: 8666 | H19: =+H18+F19-G19 -> 5759.63
A20: 10 | C20: TV CABO | G20: 5750 | H20: =+H19+F20-G20 -> 9.63
A21: 11 | B21: 45979 | C21: Reforco de caixa | F21: 60000 | H21: =+H20+F21-G21 -> 60009.63 | I21: Lev. Cheque
A22: 12 | B22: 45979 | C22: saida para esposa Otilio Jorge | G22: 30000 | H22: =+H21+F22-G22 -> 30009.63
A23: 13 | B23: 45980 | C23: Abastecimento Otilio jorge | G23: 3000 | H23: =+H22+F23-G23 -> 27009.63
A24: 14 | B24: 45981 | C24: Levantamento encomenda Otilio | G24: 3500 | H24: =+H23+F24-G24 -> 23509.63
A25: 15 | B25: 45981 | C25: Yango quinta essencia | G25: 180 | H25: =+H24+F25-G25 -> 23329.63
A26: 16 | B26: 45983 | C26: Credelec escritorio | G26: 2000 | H26: =+H25+F26-G26 -> 21329.63
A27: 17 | B27: 45985 | C27: Andre Monteiro | G27: 4000 | H27: =+H26+F27-G27 -> 17329.63
A28: 18 | C28: Extintor | G28: 5740 | H28: =+H27+F28-G28 -> 11589.63
A29: 19 | C29: yango nedbank | G29: 150 | H29: =+H28+F29-G29 -> 11439.63
A30: 20 | C30: yango | G30: 100 | H30: =+H29+F30-G30 -> 11339.63
A31: 21 | C31: Factura DHL | G31: 1620 | H31: =+H30+F31-G31 -> 9719.63
A32: 22 | C32: Reforco de caixa | F32: 50000 | H32: =+H31+F32-G32 -> 59719.63 | I32: Lev. Cheque 200.000 E 150.000 FOI Para senhor Edson
A33: 23 | C33: Aviso de pagamento | G33: 34697.02 | H33: =+H32+F33-G33 -> 25022.61
A34: 24 | C34: Almoco Andre | G34: 1000 | H34: =+H33+F34-G34 -> 24022.61
A35: 25 | H35: =+H34+F35-G35 -> 24022.61
A36: 26 | H36: =+H35+F36-G36 -> 24022.61
A37: 27 | H37: =+H36+F37-G37 -> 24022.61
A38: 28 | H38: =+H37+F38-G38 -> 24022.61
A39: 29 | H39: =+H38+F39-G39 -> 24022.61
A40: 30 | H40: =+H39+F40-G40 -> 24022.61
A41: 31 | H41: =+H40+F41-G41 -> 24022.61
A42: 32 | H42: =+H41+F42-G42 -> 24022.61
A43: 33 | H43: =+H42+F43-G43 -> 24022.61
...

Sheet Caixa Dezembro
C1: =+Acess!C1 -> 0
C2: =+Acess!C2 -> 0 | D2: 401761349
C3: =+Acess!C3 -> 0 | D3: 2025
C5: Entradas e Saidas Caixa
C7: a) Caixa
C8: Novembro
C10: N/O | D10: Data | E10: Descrição | F10: N° Documento | G10: Nome da Entidade | H10: Entradas | J10: Saldo | K10: Observação
C11: 1 | E11: Levantamento de cheque | H11: 260000
C12: 2 | E12: deposito no emola Otilio Jorge | I12: 170000 | J12: =SUM(H11-I12) -> 90000
C13: 3 | E13: Munincipio Estrada | I13: 66000 | J13: =+J12+H13-I13 -> 24000
C14: 5 | E14: Fotos de Presidente | I14: 910 | J14: =+J13+H14-I14 -> 23090
C15: 6 | E15: Carga aerea Acaciio | I15: 10300 | J15: =+J14+H15-I15 -> 12790
C16: 7 | E16: Deposito de Licenca | I16: 150 | J16: =+J15+H16-I16 -> 12640
C17: 8 | E17: Moldura | I17: 6400 | J17: =+J16+H17-I17 -> 6240
C18: 9 | E18: Andre Abastecimento | I18: 1000 | J18: =+J17+H18-I18 -> 5240
C19: 10 | E19: Andre carga pure | I19: 5030 | J19: =+J18+H19-I19 -> 210
C20: 11 | E20: Acacio carga | I20: 310 | J20: =+J19+H20-I20 -> -100
C21: 12 | E21: Reforco de caixa | H21: 23000 | J21: =+J20+H21-I21 -> 22900
C22: 13 | E22: Aviso | I22: 22905.42 | J22: =+J21+H22-I22 -> -5.42
C23: 14 | J23: =+J22+H23-I23 -> -5.42
C24: 15 | J24: =+J23+H24-I24 -> -5.42
C25: 16 | J25: =+J24+H25-I25 -> -5.42
C26: 17 | J26: =+J25+H26-I26 -> -5.42
C27: 18 | J27: =+J26+H27-I27 -> -5.42
C28: 19 | J28: =+J27+H28-I28 -> -5.42
C29: 20 | J29: =+J28+H29-I29 -> -5.42
C30: 21 | J30: =+J29+H30-I30 -> -5.42
C31: 22 | E31: Reforco de caixa | H31: 50000 | J31: 50000
C32: 23 | D32: DP world | I32: 12458.83 | J32: =+J31+H32-I32 -> 37541.17
C33: 24 | D33: Mpesa Otilio Jorge | I33: 25000 | J33: =+J32+H33-I33 -> 12541.17
C34: 25 | D34: Andre | I34: 1000 | J34: =+J33+H34-I34 -> 11541.17
C35: 26 | D35: Credelec | I35: 2000 | J35: =+J34+H35-I35 -> 9541.17
C36: 27 | D36: DP world | I36: 470.09 | J36: =+J35+H36-I36 -> 9071.08
C37: 28 | D37: Aviso carga pure | I37: 6500 | J37: =+J36+H37-I37 -> 2571.08
C38: 29 | D38: Retirada da carga no porto | I38: 2500 | J38: =+J37+H38-I38 -> 71.08
C39: 30
C40: 31

Sheet Regularizacao C&j
A2: EXTRATO Agosto ate Dezembro
A4: a) C&J LOGISTICA LDA
A5: MAPA DE CONTROLO MTR
A7: N/O | C7: Descrição | D7: Factura Final C&J | E7: Valor pago a C&J | F7: Valor final da C&J | G7: Saldo
A8: 1 | C8: RPM/MOZ/25-26/013 | D8: MTR | E8: 687341.15 | F8: 646879.27 | G8: =E8-F8 -> 40461.88
A9: 2 | C9: RPM/MOZ/25-26/014 | D9: MTR | E9: 138749.52 | F9: 102836.78 | G9: =G8+E9-F9 -> 76374.62
A10: 3 | C10: IN134425 | D10: MTR | E10: 193977.86 | F10: 162185.18 | G10: =G9+E10-F10 -> 108167.3
A11: 4 | C11: INV-087125 | D11: MTR | E11: 911501.53 | F11: 973286.92 | G11: =G10+E11-F11 -> 46381.91
A12: 5 | C12: INV-087121 | D12: MTR | E12: 62968.74 | F12: 61839.2 | G12: =G11+E12-F12 -> 47511.45
A13: 6 | C13: RPMSAM0625-26 | D13: MTR | E13: 1105783.6 | F13: 1071285.2 | G13: =G12+E13-F13 -> 82009.75
A14: 8 | C14: INV-087305 | D14: MTR | E14: 370578.91 | F14: 344676.18 | G14: =G13+E14-F14 -> 107912.48
A15: 9 | C15: INV-087306 | D15: MTR | E15: 271275.81 | F15: 308561.66 | G15: =G14+E15-F15 -> 70626.63
A16: 10 | C16: INV-087308 | D16: MTR | E16: 736016.22 | F16: 827895.12 | G16: =G15+E16-F16 -> -21252.27
A17: 11 | C17: NOTA DE DEBITO | D17: MTR | F17: 5800 | G17: =G16+E17-F17 -> -27052.27 | H17: h
A18: 12 | C18: IN134793 | D18: MTR | E18: 291384.82 | F18: 230042.43 | G18: =G17+E18-F18 -> 34290.12
A19: 13 | C19: POFDMCC/MOZ/2025/014 | D19: MTR | E19: 1118808.2 | F19: 1158490.1 | G19: =G18+E19-F19 -> -5391.73
A20: 14 | C20: POFDMCC/MOZ/2025/015 | D20: MTR | E20: 28363.73 | F20: 24209.93 | G20: =G19+E20-F20 -> -1237.93
A21: 15 | C21: FRETE Moamba | D21: MTR | F21: 81700 | G21: =G20+E21-F21 -> -82937.93

Sheet Regularizacao Pure Diets
A2: EXTRATO Agosto ate Dezembro
A4: a) C&J LOGISTICA LDA
A5: Novembro
A7: N/O | B7: Data | C7: Descrição | D7: N° Documento | E7: Nome da Entidade | F7: Entradas | G7: Saidas | H7: Saldo | I7: Observação
A8: 1
A9: 2 | H9: =SUM(F8-G9) -> 0
A10: 3 | H10: =+H9+F10-G10 -> 0
A11: 4 | H11: =+H10+F11-G11 -> 0
A12: 5 | H12: =+H11+F12-G12 -> 0
A13: 6 | H13: =+H12+F13-G13 -> 0
A14: 7 | H14: =+H13+F14-G14 -> 0
A15: 8 | H15: =+H14+F15-G15 -> 0
A16: 9 | H16: =+H15+F16-G16 -> 0
A17: 10 | H17: =+H16+F17-G17 -> 0
A18: 11 | H18: =+H17+F18-G18 -> 0
A19: 12 | H19: =+H18+F19-G19 -> 0
A20: 13 | H20: =+H19+F20-G20 -> 0
A21: 14 | H21: =+H20+F21-G21 -> 0
... A37: 30 | H37: =+H36+F37-G37 -> 0
H38: =+H37+F38-G38 -> 0
H39: =+H38+F39-G39 -> 0
H40: =+H39+F40-G40 -> 0
H41: =+H40+F41-G41 -> 0
H42: =+H41+F42-G42 -> 0
H43: =+H42+F43-G43 -> 0
H44: =+H43+F44-G44 -> 0
H45: =+H44+F45-G45 -> 0
H46: =+H45+F46-G46 -> 0
H47: =+H46+F47-G47 -> 0
H48: =+H47+F48-G48 -> 0
H49: =+H48+F49-G49 -> 0
... H57: =+H56+F57-G57 -> 0

Sheet TCO
A1: =+Acess!A1 -> Empresa: Mozambique Support Services, Lda
A2: =+Acess!A2 -> Nuit:
A3: =+Acess!A3 -> Periodo:
A6: Dividas MSS
A9: 1)
A10: N/O | B10: Data | C10: Descrição | D10: Movimentos | F10: Saldo | G10: Observação
D11: Débito | E11: CREDITO
C13: Acacio Despachantes | E13: 68778.73 | F13: =+F12+D13-E13 -> -68778.73
C14: C&J LOGISTICA | E14: 82937.93 | F14: =+F13+D14-E14 -> -151716.66
C15: QUINTA ESSENCIA | E15: 512390.9 | F15: =+F14+D15-E15 -> -664107.56
F16: =+F15+D16-E16 -> -664107.56
F17: =+F16+D17-E17 -> -664107.56
F18: =+F17+D18-E18 -> -664107.56
F19: =+F18+D19-E19 -> -664107.56
B21: Total | D21: =SUM(D12:D19) -> 0 | E21: =SUM(E12:E19) -> 664107.56 | F21: =D21-E21 -> -664107.56
